Workbook

Sheet MASTER
A1: MASTER FEASIBILITY SUMMARY — All Phases | 整地汇总
A2: Green = cross-sheet formula | Gray phase = indicative only, subject to planning approval and market review
B3: Phase 1 | C3: Phase 2 | D3: Phase 3
B4: Phase 1 精算 ✓ | C4: Phase 2 概念 ◑ | D4: Phase 3 TBC ○ | E4: TOTAL | F4: P1 %GDV | G4: P2 %GDV | H4: P3 %GDV
A5: LAND & AREA
A6: Net Developable Area (NDA) | B6: =P1_INPUT!B12 | C6: =P2_INPUT!B12 | D6: =P3_INPUT!B12 | E6: =SUM(B6:D6)
A7: Gross Floor Area (GFA sqft) | B7: =P1_INPUT!B14 | C7: =P2_INPUT!B14 | D7: =P3_INPUT!B14 | E7: =SUM(B7:D7)
A8: Nett Floor Area (NFA sqft) | B8: =P1_INPUT!B16 | C8: =P2_INPUT!B16 | D8: =P3_INPUT!B16 | E8: =SUM(B8:D8)
A9: Total Units (estimate) | B9: =P1_INPUT!B18 | C9: =P2_INPUT!B18 | D9: =P3_INPUT!B18 | E9: =SUM(B9:D9)
A11: GDV
A12: Net GDV | B12: =P1_INPUT!B34 | C12: =P2_INPUT!B34 | D12: =P3_INPUT!B24 | E12: =SUM(B12:D12) | F12: =IFERROR(B12/B$6,0) | G12: =IFERROR(C12/C$6,0) | H12: =IFERROR(D12/D$6,0)
A14: GROSS DEVELOPMENT COST — 5 PILLARS
A15: P1 · Land Cost | B15: =P1_COSTING!C12 | C15: =P2_COSTING!C9 | D15: =P3_COSTING!C8 | E15: =SUM(B15:D15) | F15: =IFERROR(B15/B$6,0) | G15: =IFERROR(C15/C$6,0) | H15: =IFERROR(D15/D$6,0)
A16: P2 · Construction | B16: =P1_COSTING!C25 | C16: =P2_COSTING!C15 | D16: =P3_COSTING!C12 | E16: =SUM(B16:D16) | F16: =IFERROR(B16/B$6,0) | G16: =IFERROR(C16/C$6,0) | H16: =IFERROR(D16/D$6,0)
A17: P3 · Infra + Stat | B17: =P1_COSTING!C37 | C17: =P2_COSTING!C21 | D17: =P3_COSTING!C16 | E17: =SUM(B17:D17) | F17: =IFERROR(B17/B$6,0) | G17: =IFERROR(C17/C$6,0) | H17: =IFERROR(D17/D$6,0)
A18: P4 · Professional | B18: =P1_COSTING!C48 | C18: =P2_COSTING!C25 | D18: =P3_COSTING!C20 | E18: =SUM(B18:D18) | F18: =IFERROR(B18/B$6,0) | G18: =IFERROR(C18/C$6,0) | H18: =IFERROR(D18/D$6,0)
A19: P5 · Finance + Mktg | B19: =P1_COSTING!C59 | C19: =P2_COSTING!C30 | D19: =P3_COSTING!C24 | E19: =SUM(B19:D19) | F19: =IFERROR(B19/B$6,0) | G19: =IFERROR(C19/C$6,0) | H19: =IFERROR(D19/D$6,0)
A20: GROSS DEVELOPMENT COST (GDC) | B20: =SUM(B15:B19) | C20: =SUM(C15:C19) | D20: =SUM(D15:D19) | E20: =SUM(B20:D20) | F20: =IFERROR(B20/B12,0) | G20: =IFERROR(C20/C12,0) | H20: =IFERROR(D20/D12,0)
A22: PROFIT BEFORE TAX (PBT) | B22: =B12-B20 | C22: =C12-C20 | D22: =D12-D20 | E22: =SUM(B22:D22) | F22: =IFERROR(B22/B12,0) | G22: =IFERROR(C22/C12,0) | H22: =IFERROR(D22/D12,0)
A24: KEY RATIOS & CHECKS
A25: Profit Margin (PBT / Net GDV) | B25: =IFERROR(B22/B12,0) | C25: =IFERROR(C22/C12,0) | D25: =IFERROR(D22/D12,0) | E25: =IFERROR(E22/E12,0)
A26: Land Cost / Net GDV | B26: =IFERROR(B15/B12,0) | C26: =IFERROR(C15/C12,0) | D26: =IFERROR(D15/D12,0) | E26: =IFERROR(E15/E12,0)
A27: Construction Cost / Net GDV | B27: =IFERROR(B16/B12,0) | C27: =IFERROR(C16/C12,0) | D27: =IFERROR(D16/D12,0) | E27: =IFERROR(E16/E12,0)
A29: ⚠ Phase 3 numbers are INDICATIVE ONLY — pending planning approval and market study. Do not use for Board commitment.

Sheet P1_INPUT
A1: Phase 1 — High-rise Resi (精算) | INPUT ASSUMPTIONS | 状态：精算 — 已规划 ✓
A2: Blue = hardcoded input | Black = calculated | Gray = TBC / indicative only
A4: A · PROJECT INFORMATION
A5: Phase Name | B5: Phase 1 — High-rise Resi (精算)
A6: Product Type | B6: High-rise Residential
A7: Target Launch Date | B7: Mar 2025
A8: Target VP Date | B8: Dec 2027
A9: Construction Period | B9: 30 | C9: months
A11: B · AREA PARAMETERS
A12: Net Developable Area (NDA) | B12: 4 | C12: acres | D12: This phase's allocated NDA
A13: Plot Ratio | B13: 3.5 | D13: Per planning approval / assumed
A14: Gross Floor Area (GFA) | B14: =B12*43560*B13 | C14: sqft | D14: NDA × 43,560 × Plot Ratio
A15: Efficiency Ratio | B15: 0.78 | C15: % | D15: GFA → NFA sellable area
A16: Nett Floor Area (NFA) — Sellable | B16: =B14*B15 | C16: sqft | D16: Base for all psf calculations
A17: Average Unit Size | B17: 900 | C17: sqft
A18: Total Units (estimate) | B18: =ROUND(B16/B17,0) | C18: units | D18: NFA ÷ avg unit size
A20: C · GDV ASSUMPTIONS
A21: Average Selling Price (ASP) | B21: 650 | C21: RM psf NFA | D21: Open market; based on market study
A22: Bumi Quota % | B22: 0.3 | C22: % | D22: Per DA conditions
A23: Bumi Discount % | B23: 0.07 | C23: % | D23: Applied to Bumi units only
A24: Affordable / Low-cost % | B24: 0.1 | C24: %
A25: Affordable Unit Price (RM/unit) | B25: 42000 | C25: RM/unit | D25: Fixed by authority
A26: Car Park Bays (extra sold) | B26: 80 | C26: bays
A27: Car Park Price / Bay | B27: 45000 | C27: RM/bay
A29: Gross GDV (open market) | B29: =B16*B21 | C29: RM | D29: NFA × ASP
A30: Less: Bumi Discount | B30: =-(B16*B22*B21*B23) | C30: RM | D30: Bumi NFA × ASP × disc%
A31: Less: Affordable Subsidy | B31: =-(B18*B24*(B21*B17-B25)) | C31: RM | D31: Units × aff% × (mkt−fixed price)
A32: Car Park Revenue | B32: =B26*B27 | C32: RM
A34: NET GDV | B34: =SUM(B29:B32) | C34: RM | D34: Gross GDV − Bumi Discount − Affordable subsidy + Car Park

Sheet P1_COSTING
A1: Phase 1 — High-rise Resi (精算) | GDC — 5 PILLARS COSTING | 精算 — 已规划 ✓
A2: C = Budget (RM) | D = Committed | E = Actual | G = Budget psf NFA | I = % of Net GDV
A3: # | B3: Cost Item | C3: Budget (RM) | D3: Committed (RM) | E3: Actual (RM) | F3: Variance | G3: Budget psf | H3: Actual psf | I3: % Net GDV
A5: P1 | B5: PILLAR 1 · LAND COST | I5: Target: 15–25% Net GDV
A6: 1.1 | B6: Land Purchase Price (this phase share) | C6: 12000000 | D6: 0 | E6: 0 | F6: =C6-E6 | G6: =IFERROR(C6/P1_INPUT!B16,0) | H6: =IFERROR(E6/P1_INPUT!B16,0) | I6: Allocated by NDA % from master land cost
A7: 1.2 | B7: Stamp Duty | C7: =IFERROR(IF(C6<=100000,C6*0.01,IF(C6<=500000,1000+(C6-100000)*0.02,IF(C6<=1000000,9000+(C6-500000)*0.03,24000+(C6-1000000)*0.04))),0) | D7: 0 | E7: 0 | F7: =C7-E7 | G7: =IFERROR(C7/P1_INPUT!B16,0) | H7: =IFERROR(E7/P1_INPUT!B16,0) | I7: Tiered 1/2/3/4%
A8: 1.3 | B8: Legal Fees | C8: =C6*0.01 | D8: 0 | E8: 0 | F8: =C8-E8 | G8: =IFERROR(C8/P1_INPUT!B16,0) | H8: =IFERROR(E8/P1_INPUT!B16,0) | I8: ~1% of land price
A9: 1.4 | B9: Conversion Premium | C9: 500000 | D9: 0 | E9: 0 | F9: =C9-E9 | G9: =IFERROR(C9/P1_INPUT!B16,0) | H9: =IFERROR(E9/P1_INPUT!B16,0) | I9: Agri→Building; state authority
A10: 1.5 | B10: Holding Interest (land loan) | C10: 400000 | D10: 0 | E10: 0 | F10: =C10-E10 | G10: =IFERROR(C10/P1_INPUT!B16,0) | H10: =IFERROR(E10/P1_INPUT!B16,0) | I10: Land loan interest to launch
A11: 1.6 | B11: Valuation + Misc | C11: =C6*0.004 | D11: 0 | E11: 0 | F11: =C11-E11 | G11: =IFERROR(C11/P1_INPUT!B16,0) | H11: =IFERROR(E11/P1_INPUT!B16,0) | I11: Valuer + misc legal
B12: PILLAR 1 TOTAL | C12: =SUM(C6:C11) | D12: =SUM(D6:D11) | E12: =SUM(E6:E11) | F12: =C12-E12 | G12: =IFERROR(C12/P1_INPUT!B16,0) | H12: =IFERROR(E12/P1_INPUT!B16,0) | I12: =IFERROR(C12/P1_INPUT!B34,0)
A14: P2 | B14: PILLAR 2 · CONSTRUCTION COST | I14: Target: 45–50% Net GDV
A15: 2.1 | B15: Piling Works | C15: 3200000 | D15: 0 | E15: 0 | F15: =C15-E15 | G15: =IFERROR(C15/P1_INPUT!B16,0) | H15: =IFERROR(E15/P1_INPUT!B16,0) | I15: Bored/driven per soil report
A16: 2.2 | B16: Substructure | C16: 2600000 | D16: 0 | E16: 0 | F16: =C16-E16 | G16: =IFERROR(C16/P1_INPUT!B16,0) | H16: =IFERROR(E16/P1_INPUT!B16,0) | I16: Foundation, pile caps, basement
A17: 2.3 | B17: Superstructure — C&S | C17: 15200000 | D17: 0 | E17: 0 | F17: =C17-E17 | G17: =IFERROR(C17/P1_INPUT!B16,0) | H17: =IFERROR(E17/P1_INPUT!B16,0) | I17: RC frame, beams, slabs
A18: 2.4 | B18: Architectural Works | C18: 8800000 | D18: 0 | E18: 0 | F18: =C18-E18 | G18: =IFERROR(C18/P1_INPUT!B16,0) | H18: =IFERROR(E18/P1_INPUT!B16,0) | I18: Façade, partitions, finishes
A19: 2.5 | B19: M&E — Mechanical | C19: 3600000 | D19: 0 | E19: 0 | F19: =C19-E19 | G19: =IFERROR(C19/P1_INPUT!B16,0) | H19: =IFERROR(E19/P1_INPUT!B16,0) | I19: HVAC, fire, lifts
A20: 2.6 | B20: M&E — Electrical | C20: 3000000 | D20: 0 | E20: 0 | F20: =C20-E20 | G20: =IFERROR(C20/P1_INPUT!B16,0) | H20: =IFERROR(E20/P1_INPUT!B16,0) | I20: LV/HV, lighting, ELV
A21: 2.7 | B21: Plumbing & Sanitary | C21: 1600000 | D21: 0 | E21: 0 | F21: =C21-E21 | G21: =IFERROR(C21/P1_INPUT!B16,0) | H21: =IFERROR(E21/P1_INPUT!B16,0) | I21: Water supply & sewerage
A22: 2.8 | B22: Landscaping (Internal) | C22: 800000 | D22: 0 | E22: 0 | F22: =C22-E22 | G22: =IFERROR(C22/P1_INPUT!B16,0) | H22: =IFERROR(E22/P1_INPUT!B16,0) | I22: Podium, pool, gym
A23: 2.9 | B23: Preliminaries | C23: =SUM(C15:C22)*0.08 | D23: 0 | E23: 0 | F23: =C23-E23 | G23: =IFERROR(C23/P1_INPUT!B16,0) | H23: =IFERROR(E23/P1_INPUT!B16,0) | I23: ~8% of trade works
A24: 2.10 | B24: Contingency (5%) | C24: =SUM(C15:C23)*0.05 | D24: 0 | E24: 0 | F24: =C24-E24 | G24: =IFERROR(C24/P1_INPUT!B16,0) | H24: =IFERROR(E24/P1_INPUT!B16,0) | I24: For approved VOs
B25: PILLAR 2 TOTAL | C25: =SUM(C15:C24) | D25: =SUM(D15:D24) | E25: =SUM(E15:E24) | F25: =C25-E25 | G25: =IFERROR(C25/P1_INPUT!B16,0) | H25: =IFERROR(E25/P1_INPUT!B16,0) | I25: =IFERROR(C25/P1_INPUT!B34,0)
A27: P3 | B27: PILLAR 3 · INFRASTRUCTURE + STATUTORY | I27: Target: 8–15% Net GDV
A28: 3.1 | B28: Internal Roads | C28: 1400000 | D28: 0 | E28: 0 | F28: =C28-E28 | G28: =IFERROR(C28/P1_INPUT!B16,0) | H28: =IFERROR(E28/P1_INPUT!B16,0) | I28: Tarmac, curbs, markings
A29: 3.2 | B29: External Road (JKR) | C29: 700000 | D29: 0 | E29: 0 | F29: =C29-E29 | G29: =IFERROR(C29/P1_INPUT!B16,0) | H29: =IFERROR(E29/P1_INPUT!B16,0) | I29: Off-site widening per JKR
A30: 3.3 | B30: Drainage (JPS) | C30: 880000 | D30: 0 | E30: 0 | F30: =C30-E30 | G30: =IFERROR(C30/P1_INPUT!B16,0) | H30: =IFERROR(E30/P1_INPUT!B16,0) | I30: Internal + tie-in to JPS
A31: 3.4 | B31: TNB Substation | C31: 600000 | D31: 0 | E31: 0 | F31: =C31-E31 | G31: =IFERROR(C31/P1_INPUT!B16,0) | H31: =IFERROR(E31/P1_INPUT!B16,0) | I31: Substation contribution + cabling
A32: 3.5 | B32: Water Supply | C32: 360000 | D32: 0 | E32: 0 | F32: =C32-E32 | G32: =IFERROR(C32/P1_INPUT!B16,0) | H32: =IFERROR(E32/P1_INPUT!B16,0) | I32: Pipe + reservoir contribution
A33: 3.6 | B33: Sewerage (IWK) | C33: 280000 | D33: 0 | E33: 0 | F33: =C33-E33 | G33: =IFERROR(C33/P1_INPUT!B16,0) | H33: =IFERROR(E33/P1_INPUT!B16,0) | I33: IWK connection / on-site STP
A34: 3.7 | B34: Open Space + Amenities | C34: 480000 | D34: 0 | E34: 0 | F34: =C34-E34 | G34: =IFERROR(C34/P1_INPUT!B16,0) | H34: =IFERROR(E34/P1_INPUT!B16,0) | I34: 10% site area; bus stop, surau
A35: 3.8 | B35: Development Contribution | C35: 1000000 | D35: 0 | E35: 0 | F35: =C35-E35 | G35: =IFERROR(C35/P1_INPUT!B16,0) | H35: =IFERROR(E35/P1_INPUT!B16,0) | I35: Cash to local authority (DA cond)
A36: 3.9 | B36: Contingency (5%) | C36: =SUM(C28:C35)*0.05 | D36: 0 | E36: 0 | F36: =C36-E36 | G36: =IFERROR(C36/P1_INPUT!B16,0) | H36: =IFERROR(E36/P1_INPUT!B16,0)
B37: PILLAR 3 TOTAL | C37: =SUM(C28:C36) | D37: =SUM(D28:D36) | E37: =SUM(E28:E36) | F37: =C37-E37 | G37: =IFERROR(C37/P1_INPUT!B16,0) | H37: =IFERROR(E37/P1_INPUT!B16,0) | I37: =IFERROR(C37/P1_INPUT!B34,0)
A39: P4 | B39: PILLAR 4 · PROFESSIONAL FEES | I39: Target: 3–5% Net GDV
A40: 4.1 | B40: Architect | C40: =C25*0.04 | D40: 0 | E40: 0 | F40: =C40-E40 | G40: =IFERROR(C40/P1_INPUT!B16,0) | H40: =IFERROR(E40/P1_INPUT!B16,0) | I40: ~4% of construction cost
A41: 4.2 | B41: Structural Engineer | C41: =C17*0.015 | D41: 0 | E41: 0 | F41: =C41-E41 | G41: =IFERROR(C41/P1_INPUT!B16,0) | H41: =IFERROR(E41/P1_INPUT!B16,0) | I41: ~1.5% of C&S
A42: 4.3 | B42: M&E Engineer | C42: =(C19+C20)*0.015 | D42: 0 | E42: 0 | F42: =C42-E42 | G42: =IFERROR(C42/P1_INPUT!B16,0) | H42: =IFERROR(E42/P1_INPUT!B16,0) | I42: ~1.5% of M&E
A43: 4.4 | B43: QS | C43: =C25*0.01 | D43: 0 | E43: 0 | F43: =C43-E43 | G43: =IFERROR(C43/P1_INPUT!B16,0) | H43: =IFERROR(E43/P1_INPUT!B16,0) | I43: ~1% of construction
A44: 4.5 | B44: Land Surveyor | C44: 30000 | D44: 0 | E44: 0 | F44: =C44-E44 | G44: =IFERROR(C44/P1_INPUT!B16,0) | H44: =IFERROR(E44/P1_INPUT!B16,0) | I44: Boundary + strata survey
...

Sheet P1_CASHFLOW
A1: PHASE 1 — DEVELOPMENT CASH FLOW & IRR
A2: Yearly model · Blue = input · Black = calc · Green = link to P1_INPUT / P1_COSTING
A4: ASSUMPTIONS & CURVES
B5: Σ / Param | C5: Y0 | D5: Y1 | E5: Y2 | F5: Y3 | G5: Y4 | H5: Notes
A6: GDC spend curve (non-land) | B6: =SUM(C6:G6) | C6: 0.1 | D6: 0.3 | E6: 0.35 | F6: 0.2 | G6: 0.05 | H6: Land booked Y0; rest follows construction S-curve
A7: Revenue collection curve | B7: =SUM(C7:G7) | C7: 0.03 | D7: 0.2 | E7: 0.35 | F7: 0.3 | G7: 0.12 | H7: Cash actually collected — drives inflow. Σ must = 100%
A8: ref: HDA Sch.H billing | B8: =SUM(C8:G8) | C8: 0.1 | D8: 0.3 | E8: 0.35 | F8: 0.2 | G8: 0.05 | H8: Statutory billing milestones (reference only)
A9: ref: Sales take-up (RoS) | B9: =SUM(C9:G9) | C9: 0.2 | D9: 0.35 | E9: 0.25 | F9: 0.15 | G9: 0.05 | H9: Units sold per year (reference only)
A10: Discount rate (WACC) | B10: 0.1 | H10: For NPV. Adjust to project hurdle / cost of capital
A12: CASH OUTFLOW (RM)
A13: Land Cost (P1) | B13: ='P1_COSTING'!C12 | C13: =B13 | D13: 0 | E13: 0 | F13: 0 | G13: 0
A14: Development Cost (P2–P5) | B14: ='P1_COSTING'!C61-'P1_COSTING'!C12 | C14: =$B14*C6 | D14: =$B14*D6 | E14: =$B14*E6 | F14: =$B14*F6 | G14: =$B14*G6
A15: TOTAL OUTFLOW | B15: =B13+B14 | C15: =C13+C14 | D15: =D13+D14 | E15: =E13+E14 | F15: =F13+F14 | G15: =G13+G14
A17: CASH INFLOW (RM)
A18: Net GDV (link) | B18: ='P1_INPUT'!B34
A19: Revenue Collected | B19: =SUM(C19:G19) | C19: =$B$18*C7 | D19: =$B$18*D7 | E19: =$B$18*E7 | F19: =$B$18*F7 | G19: =$B$18*G7
A20: TOTAL INFLOW | B20: =B19 | C20: =C19 | D20: =D19 | E20: =E19 | F20: =F19 | G20: =G19
A22: NET CASH FLOW
A23: Net Cash Flow | B23: =B20-B15 | C23: =C20-C15 | D23: =D20-D15 | E23: =E20-E15 | F23: =F20-F15 | G23: =G20-G15
A24: Cumulative Cash Flow | C24: =C23 | D24: =C24+D23 | E24: =D24+E23 | F24: =E24+F23 | G24: =F24+G23
A26: RETURNS
A27: Project IRR (annual) | B27: =IRR(C23:G23) | H27: Computes only if ≥1 negative year. HIGH here because land=4.9% of GDV + progress billing → tiny equity at risk. Read alongside Peak funding & NPV.
A28: NPV @ WACC | B28: =NPV(B10,D23:G23)+C23 | H28: >0 = value-accretive
A29: Years to turn cash-positive | B29: =COUNTIF(C24:G24,"<0") | H29: Approx payback in years
A30: Peak funding need | B30: =MIN(C24:G24) | H30: Most negative cumulative = max capital at risk
A31: PBT (static) | B31: ='P1_INPUT'!B34-'P1_COSTING'!C61 | H31: Net GDV − GDC
A32: Profit margin | B32: =B31/'P1_INPUT'!B34 | H32: PBT / Net GDV
A34: ⚠ CHECK: collection curve (row 7) Σ must = 100%; revenue B19 must ≈ Net GDV B18
A35: NOTE: with so little land cost, the developer is nearly self-funding; project IRR overstates attractiveness — Peak funding need (B30) and NPV (B28) are the steadier signals.

Sheet P2_INPUT
A1: Phase 2 — High-rise Resi (概念) | INPUT ASSUMPTIONS | 状态：概念阶段 ◑
A2: Blue = hardcoded input | Black = calculated | Gray = TBC / indicative only
A4: A · PROJECT INFORMATION
A5: Phase Name | B5: Phase 2 — High-rise Resi (概念)
A6: Product Type | B6: High-rise Residential (Phase 2)
A7: Target Launch Date | B7: Q3 2026
A8: Target VP Date | B8: Dec 2028
A9: Construction Period | B9: 32 | C9: months
A11: B · AREA PARAMETERS
A12: Net Developable Area (NDA) | B12: 3.5 | C12: acres | D12: This phase's allocated NDA
A13: Plot Ratio | B13: 3.5 | D13: Per planning approval / assumed
A14: Gross Floor Area (GFA) | B14: =B12*43560*B13 | C14: sqft | D14: NDA × 43,560 × Plot Ratio
A15: Efficiency Ratio | B15: 0.78 | C15: % | D15: GFA → NFA sellable area
A16: Nett Floor Area (NFA) — Sellable | B16: =B14*B15 | C16: sqft | D16: Base for all psf calculations
A17: Average Unit Size | B17: 950 | C17: sqft
A18: Total Units (estimate) | B18: =ROUND(B16/B17,0) | C18: units | D18: NFA ÷ avg unit size
A20: C · GDV ASSUMPTIONS
A21: Average Selling Price (ASP) | B21: 680 | C21: RM psf NFA | D21: Open market; based on market study
A22: Bumi Quota % | B22: 0.3 | C22: % | D22: Per DA conditions
A23: Bumi Discount % | B23: 0.07 | C23: % | D23: Applied to Bumi units only
A24: Affordable / Low-cost % | B24: 0.1 | C24: %
A25: Affordable Unit Price (RM/unit) | B25: 42000 | C25: RM/unit | D25: Fixed by authority
A26: Car Park Bays (extra sold) | B26: 60 | C26: bays
A27: Car Park Price / Bay | B27: 47000 | C27: RM/bay
A29: Gross GDV (open market) | B29: =B16*B21 | C29: RM | D29: NFA × ASP
A30: Less: Bumi Discount | B30: =-(B16*B22*B21*B23) | C30: RM | D30: Bumi NFA × ASP × disc%
A31: Less: Affordable Subsidy | B31: =-(B18*B24*(B21*B17-B25)) | C31: RM | D31: Units × aff% × (mkt−fixed price)
A32: Car Park Revenue | B32: =B26*B27 | C32: RM
A34: NET GDV | B34: =SUM(B29:B32) | C34: RM | D34: Gross GDV − Bumi Discount − Affordable subsidy + Car Park

Sheet P2_COSTING
A1: Phase 2 — High-rise Resi (概念) | GDC — 5 PILLARS COSTING | 概念阶段 ◑
A2: C = Budget (RM) | D = Committed | E = Actual | G = Budget psf NFA | I = % of Net GDV
A3: # | B3: Cost Item | C3: Budget (RM) | D3: Committed (RM) | E3: Actual (RM) | F3: Variance | G3: Budget psf | H3: Actual psf | I3: % Net GDV
A5: P1 | B5: PILLAR 1 · LAND COST | I5: Target: 15–25% Net GDV
A6: 1.1 | B6: Land Price (phase share) | C6: 10500000 | D6: 0 | E6: 0 | F6: =C6-E6 | G6: =IFERROR(C6/P2_INPUT!B16,0) | H6: =IFERROR(E6/P2_INPUT!B16,0) | I6: Allocated from master land cost by NDA%
A7: 1.2 | B7: Transaction costs (stamp/legal) | C7: =C6*0.055 | D7: 0 | E7: 0 | F7: =C7-E7 | G7: =IFERROR(C7/P2_INPUT!B16,0) | H7: =IFERROR(E7/P2_INPUT!B16,0) | I7: Stamp + legal ~5.5% of land price
A8: 1.3 | B8: Conversion + Holding Interest | C8: 1000000 | D8: 0 | E8: 0 | F8: =C8-E8 | G8: =IFERROR(C8/P2_INPUT!B16,0) | H8: =IFERROR(E8/P2_INPUT!B16,0) | I8: Combined estimate; refine at planning stage
B9: PILLAR 1 TOTAL | C9: =SUM(C6:C8) | D9: =SUM(D6:D8) | E9: =SUM(E6:E8) | F9: =C9-E9 | G9: =IFERROR(C9/P2_INPUT!B16,0) | H9: =IFERROR(E9/P2_INPUT!B16,0) | I9: =IFERROR(C9/P2_INPUT!B34,0)
A11: P2 | B11: PILLAR 2 · CONSTRUCTION COST | I11: Target: 45–50% Net GDV
A12: 2.1 | B12: Main Building (C&S + Arch) | C12: 23200000 | D12: 0 | E12: 0 | F12: =C12-E12 | G12: =IFERROR(C12/P2_INPUT!B16,0) | H12: =IFERROR(E12/P2_INPUT!B16,0) | I12: Estimated at RM 320 psf GFA
A13: 2.2 | B13: M&E Complete | C13: 7175000 | D13: 0 | E13: 0 | F13: =C13-E13 | G13: =IFERROR(C13/P2_INPUT!B16,0) | H13: =IFERROR(E13/P2_INPUT!B16,0) | I13: Estimated at RM 90 psf GFA
A14: 2.3 | B14: Piling + Prelim + Contingency | C14: =SUM(C12:C13)*0.15 | D14: 0 | E14: 0 | F14: =C14-E14 | G14: =IFERROR(C14/P2_INPUT!B16,0) | H14: =IFERROR(E14/P2_INPUT!B16,0) | I14: ~15% of main works
B15: PILLAR 2 TOTAL | C15: =SUM(C12:C14) | D15: =SUM(D12:D14) | E15: =SUM(E12:E14) | F15: =C15-E15 | G15: =IFERROR(C15/P2_INPUT!B16,0) | H15: =IFERROR(E15/P2_INPUT!B16,0) | I15: =IFERROR(C15/P2_INPUT!B34,0)
A17: P3 | B17: PILLAR 3 · INFRASTRUCTURE + STATUTORY | I17: Target: 8–15% Net GDV
A18: 3.1 | B18: Infrastructure Works | C18: 3650000 | D18: 0 | E18: 0 | F18: =C18-E18 | G18: =IFERROR(C18/P2_INPUT!B16,0) | H18: =IFERROR(E18/P2_INPUT!B16,0) | I18: Roads, drainage, TNB, water — estimated
A19: 3.2 | B19: Statutory Contributions | C19: 1295000 | D19: 0 | E19: 0 | F19: =C19-E19 | G19: =IFERROR(C19/P2_INPUT!B16,0) | H19: =IFERROR(E19/P2_INPUT!B16,0) | I19: Open space + dev contribution — TBC at DA
A20: 3.3 | B20: Contingency (5%) | C20: =SUM(C18:C19)*0.05 | D20: 0 | E20: 0 | F20: =C20-E20 | G20: =IFERROR(C20/P2_INPUT!B16,0) | H20: =IFERROR(E20/P2_INPUT!B16,0)
B21: PILLAR 3 TOTAL | C21: =SUM(C18:C20) | D21: =SUM(D18:D20) | E21: =SUM(E18:E20) | F21: =C21-E21 | G21: =IFERROR(C21/P2_INPUT!B16,0) | H21: =IFERROR(E21/P2_INPUT!B16,0) | I21: =IFERROR(C21/P2_INPUT!B34,0)
A23: P4 | B23: PILLAR 4 · PROFESSIONAL FEES | I23: Target: 3–5% Net GDV
A24: 4.1 | B24: All Consultants (combined) | C24: 450000 | D24: 0 | E24: 0 | F24: =C24-E24 | G24: =IFERROR(C24/P2_INPUT!B16,0) | H24: =IFERROR(E24/P2_INPUT!B16,0) | I24: Archi + Struct + ME + QS + Legal — estimated
B25: PILLAR 4 TOTAL | C25: =SUM(C24:C24) | D25: =SUM(D24:D24) | E25: =SUM(E24:E24) | F25: =C25-E25 | G25: =IFERROR(C25/P2_INPUT!B16,0) | H25: =IFERROR(E25/P2_INPUT!B16,0) | I25: =IFERROR(C25/P2_INPUT!B34,0)
A27: P5 | B27: PILLAR 5 · FINANCE + MARKETING | I27: Target: 6–10% Net GDV
A28: 5.1 | B28: Finance Cost (IDC + fees) | C28: 4600000 | D28: 0 | E28: 0 | F28: =C28-E28 | G28: =IFERROR(C28/P2_INPUT!B16,0) | H28: =IFERROR(E28/P2_INPUT!B16,0) | I28: Estimate; refine with loan term
A29: 5.2 | B29: Marketing + Agent Commission | C29: =P2_INPUT!B34*0.025+680000 | D29: 0 | E29: 0 | F29: =C29-E29 | G29: =IFERROR(C29/P2_INPUT!B16,0) | H29: =IFERROR(E29/P2_INPUT!B16,0) | I29: 2.5% agent + est. gallery/mktg
B30: PILLAR 5 TOTAL | C30: =SUM(C28:C29) | D30: =SUM(D28:D29) | E30: =SUM(E28:E29) | F30: =C30-E30 | G30: =IFERROR(C30/P2_INPUT!B16,0) | H30: =IFERROR(E30/P2_INPUT!B16,0) | I30: =IFERROR(C30/P2_INPUT!B34,0)
A32: GDC | B32: GROSS DEVELOPMENT COST | C32: =C9+C15+C21+C25+C30 | D32: =D9+D15+D21+D25+D30 | E32: =E9+E15+E21+E25+E30 | F32: =C32-E32 | G32: =IFERROR(C32/P2_INPUT!B16,0) | H32: =IFERROR(E32/P2_INPUT!B16,0) | I32: =IFERROR(C32/P2_INPUT!B34,0)
A34: PBT | B34: PROFIT BEFORE TAX (Net GDV − GDC) | C34: =P2_INPUT!B34-C32 | G34: =IFERROR(C34/P2_INPUT!B16,0) | I34: =IFERROR(C34/P2_INPUT!B34,0)

Sheet P3_INPUT
A1: Phase 3 — Mixed TBC (占位) | INPUT ASSUMPTIONS | 状态：未规划 TBC ○
A2: Blue = hardcoded input | Black = calculated | Gray = TBC / indicative only
A4: A · PROJECT INFORMATION
A5: Phase Name | B5: Phase 3 — Mixed TBC (占位)
A6: Product Type | B6: Mixed / TBD
A7: Target Launch Date | B7: TBD
A8: Target VP Date | B8: TBD
A9: Construction Period | B9: 36 | C9: months
A11: B · AREA PARAMETERS
A12: Net Developable Area (NDA) | B12: 2.5 | C12: acres | D12: This phase's allocated NDA
A13: Plot Ratio | B13: 3 | D13: Per planning approval / assumed
A14: Gross Floor Area (GFA) | B14: =B12*43560*B13 | C14: sqft | D14: NDA × 43,560 × Plot Ratio
A15: Efficiency Ratio | B15: 0.75 | C15: % | D15: GFA → NFA sellable area
A16: Nett Floor Area (NFA) — Sellable | B16: =B14*B15 | C16: sqft | D16: Base for all psf calculations
A17: Average Unit Size | B17: 900 | C17: sqft
A18: Total Units (estimate) | B18: =ROUND(B16/B17,0) | C18: units | D18: NFA ÷ avg unit size
A20: C · GDV ASSUMPTIONS
A21: GDV per Nett Acre (benchmark) | B21: 22000000 | C21: RM/acre | D21: From comparable completed projects in area
A22: Estimated Gross GDV | B22: =B12*B21 | C22: RM | D22: NDA × GDV/acre | INDICATIVE ONLY
A23: Bumi Discount Provision | B23: 3000000 | C23: RM | D23: Flat provision; refine when planning known
A24: NET GDV (indicative) | B24: =B22-B23 | C24: RM | D24: TBC — pending planning & market study

Sheet P3_COSTING
A1: Phase 3 — Mixed TBC (占位) | GDC — 5 PILLARS COSTING | 未规划 TBC ○
A2: C = Budget (RM) | D = Committed | E = Actual | G = Budget psf NFA | I = % of Net GDV
A3: # | B3: Cost Item | C3: Budget (RM) | D3: Committed (RM) | E3: Actual (RM) | F3: Variance | G3: Budget psf | H3: Actual psf | I3: % Net GDV
A5: P1 | B5: PILLAR 1 · LAND COST (indicative) | I5: TBC
A6: 1.1 | B6: Land Cost (NDA share) | C6: 7500000 | D6: 0 | E6: 0 | F6: =C6-E6 | G6: =IFERROR(C6/P3_INPUT!B16,0) | H6: =IFERROR(E6/P3_INPUT!B16,0) | I6: Allocated from master by NDA%; TBC
A7: 1.2 | B7: Transaction costs | C7: =C6*0.055 | D7: 0 | E7: 0 | F7: =C7-E7 | G7: =IFERROR(C7/P3_INPUT!B16,0) | H7: =IFERROR(E7/P3_INPUT!B16,0) | I7: Stamp + legal estimate
B8: PILLAR 1 TOTAL | C8: =SUM(C6:C7) | D8: =SUM(D6:D7) | E8: =SUM(E6:E7) | F8: =C8-E8 | G8: =IFERROR(C8/P3_INPUT!B16,0) | H8: =IFERROR(E8/P3_INPUT!B16,0) | I8: =IFERROR(C8/P3_INPUT!B24,0)
A10: P2 | B10: PILLAR 2 · CONSTRUCTION COST (indicative) | I10: TBC
A11: 2.1 | B11: Construction (psf GFA estimate) | C11: 111078000 | D11: 0 | E11: 0 | F11: =C11-E11 | G11: =IFERROR(C11/P3_INPUT!B16,0) | H11: =IFERROR(E11/P3_INPUT!B16,0) | I11: RM 300–380 psf GFA benchmark; TBC at design
B12: PILLAR 2 TOTAL | C12: =SUM(C11:C11) | D12: =SUM(D11:D11) | E12: =SUM(E11:E11) | F12: =C12-E12 | G12: =IFERROR(C12/P3_INPUT!B16,0) | H12: =IFERROR(E12/P3_INPUT!B16,0) | I12: =IFERROR(C12/P3_INPUT!B24,0)
A14: P3 | B14: PILLAR 3 · INFRASTRUCTURE + STATUTORY (indicative) | I14: TBC
A15: 3.1 | B15: Infrastructure + Statutory | C15: =C12*0.2 | D15: 0 | E15: 0 | F15: =C15-E15 | G15: =IFERROR(C15/P3_INPUT!B16,0) | H15: =IFERROR(E15/P3_INPUT!B16,0) | I15: ~20% of construction; TBC at DA stage
B16: PILLAR 3 TOTAL | C16: =SUM(C15:C15) | D16: =SUM(D15:D15) | E16: =SUM(E15:E15) | F16: =C16-E16 | G16: =IFERROR(C16/P3_INPUT!B16,0) | H16: =IFERROR(E16/P3_INPUT!B16,0) | I16: =IFERROR(C16/P3_INPUT!B24,0)
A18: P4 | B18: PILLAR 4 · PROFESSIONAL FEES (indicative) | I18: TBC
A19: 4.1 | B19: All Consultants | C19: =C12*0.06 | D19: 0 | E19: 0 | F19: =C19-E19 | G19: =IFERROR(C19/P3_INPUT!B16,0) | H19: =IFERROR(E19/P3_INPUT!B16,0) | I19: ~6% of construction; TBC
B20: PILLAR 4 TOTAL | C20: =SUM(C19:C19) | D20: =SUM(D19:D19) | E20: =SUM(E19:E19) | F20: =C20-E20 | G20: =IFERROR(C20/P3_INPUT!B16,0) | H20: =IFERROR(E20/P3_INPUT!B16,0) | I20: =IFERROR(C20/P3_INPUT!B24,0)
A22: P5 | B22: PILLAR 5 · FINANCE + MARKETING (indicative) | I22: TBC
A23: 5.1 | B23: Finance + Marketing | C23: =P3_INPUT!B24*0.08 | D23: 0 | E23: 0 | F23: =C23-E23 | G23: =IFERROR(C23/P3_INPUT!B16,0) | H23: =IFERROR(E23/P3_INPUT!B16,0) | I23: ~8% Net GDV; TBC
B24: PILLAR 5 TOTAL | C24: =SUM(C23:C23) | D24: =SUM(D23:D23) | E24: =SUM(E23:E23) | F24: =C24-E24 | G24: =IFERROR(C24/P3_INPUT!B16,0) | H24: =IFERROR(E24/P3_INPUT!B16,0) | I24: =IFERROR(C24/P3_INPUT!B24,0)
A26: GDC | B26: GROSS DEV COST (INDICATIVE — TBC) | C26: =C8+C12+C16+C20+C24 | G26: =IFERROR(C26/P3_INPUT!B16,0) | I26: =IFERROR(C26/P3_INPUT!B24,0)
A28: PBT | B28: PROFIT (INDICATIVE — TBC) | C28: =P3_INPUT!B24-C26 | I28: =IFERROR(C28/P3_INPUT!B24,0)
