Workbook

Sheet INPUT
A1: PROPERTY DEVELOPMENT — COSTING TEMPLATE
A2: INPUT ASSUMPTIONS | Blue = hardcoded input | Black = calculated
A4: A · PROJECT INFORMATION
A5: Project Name | B5: Project XYZ | D5: Enter project name
A6: Developer | B6: NCT Group | D6: Developer / JV entity
A7: Location | B7: Selangor | D7: State / town
A8: Product Type | B8: High-rise Resi | D8: Residential / Commercial / Mixed
A9: Target VP Date | B9: Dec 2028 | D9: Vacant Possession target month/year
A10: Construction Period | B10: 30 | C10: months | D10: Months from piling to CCC
A12: B · LAND & AREA PARAMETERS
A13: Gross Land Area (GLA) | B13: 10 | C13: acres | D13: Per title / sale agreement
A14: Net Developable Area % (NDA%) | B14: 0.75 | C14: % | D14: After reserves, open space, river buffer
A15: Net Developable Area (NDA) | B15: =B13*B14 -> 7.5 | C15: acres | D15: GLA × NDA%
A16: Plot Ratio | B16: 3.5 | D16: Approved / assumed from pre-consultation
A17: Gross Floor Area (GFA) | B17: =B15*43560*B16 -> 1143450 | C17: sqft | D17: NDA (acres) × 43,560 × Plot Ratio
A18: Efficiency Ratio | B18: 0.78 | C18: % | D18: GFA → NFA; typical hi-rise resi 75–82%
A19: Nett Floor Area (NFA) — Sellable | B19: =B17*B18 -> 891891 | C19: sqft | D19: GFA × Efficiency Ratio — base for psf calcs
A20: Average Unit Size | B20: 900 | C20: sqft | D20: Weighted average across all unit types
A21: Total Units (estimate) | B21: =ROUND(B19/B20,0) -> 991 | C21: units | D21: NFA ÷ Avg Unit Size
A23: C · GDV ASSUMPTIONS
A24: Average Selling Price (ASP) | B24: 650 | C24: RM psf | D24: Open market residential, NFA basis
A25: Bumi Quota % | B25: 0.3 | C25: % | D25: Per planning approval requirement
A26: Bumi Discount % | B26: 0.07 | C26: % | D26: Typical 5–15%; refer DA conditions
A27: Affordable / Low-cost % | B27: 0.1 | C27: % | D27: PR1MA / RumahWIP / Selangorku etc
A28: Affordable Selling Price | B28: 42000 | C28: RM/unit | D28: Fixed by authority; not psf-based
A29: Car Park Bays (extra) | B29: 120 | C29: bays | D29: Bays sold separately beyond 1:1 allocation
A30: Car Park Price per Bay | B30: 45000 | C30: RM/bay | D30: Typical KV range RM 30k–60k
A32: → Gross GDV (Open Market) | B32: =INPUT!B19*INPUT!B24 -> 579729150 | C32: RM | D32: NFA × ASP
A33: → Less: Bumi Discount | B33: =-(INPUT!B19*INPUT!B25*INPUT!B24*INPUT!B26) -> -12174312 | C33: RM | D33: Bumi NFA × ASP × Discount%
A34: → Less: Affordable Units (cross-subsidy) | B34: =-(INPUT!B21*INPUT!B27*(INPUT!B24*INPUT!B20 - INPUT!B28)) -> -53811300 | C34: RM | D34: Units × affordable units% × (market price – fixed price)
A35: → Car Park Revenue | B35: =INPUT!B29*INPUT!B30 -> 5400000 | C35: RM | D35: Extra bays × price/bay
A37: NET GDV | B37: =SUM(B32:B35) -> 5.1914354e+08 | C37: RM | D37: Gross GDV − Bumi Disc − Affordable subsidy + Car Park

Sheet COSTING
A1: GROSS DEVELOPMENT COST — 5 PILLARS | Detailed Costing Template
A2: Blue = input | Black = formula | Green = cross-sheet link | psf based on NFA (sellable area)
A3: # | B3: Cost Item / Sub-item | C3: Budget (RM) | D3: Committed (RM) | E3: Actual (RM) | F3: Variance (RM) | G3: Budget psf NFA | H3: Actual psf NFA | I3: Notes / Source
A5: P1 | B5: PILLAR 1 · LAND COST | I5: Typical: 15–25% of Net GDV
A6: 1.1 | B6: Land Purchase Price | C6: 18000000 | D6: 18000000 | E6: 18000000 | F6: =C6-E6 -> 0 | G6: =IFERROR(C6/INPUT!$B$19,0) -> 20.181838 | H6: =IFERROR(E6/INPUT!$B$19,0) -> 20.181838 | I6: Per SPA / negotiated price
A7: 1.2 | B7: Stamp Duty on Transfer | C7: =IFERROR(IF(C6<=100000,C6*0.01,IF(C6<=500000,1000+(C6-100000)*0.02,IF(C6<=1000000,9000+(C6-500000)*0.03,24000+(C6-1000000)*0.04))),0) -> 704000 | D7: 0 | E7: 0 | F7: =C7-E7 -> 704000 | G7: =IFERROR(C7/INPUT!$B$19,0) -> 0.78933412 | H7: =IFERROR(E7/INPUT!$B$19,0) -> 0 | I7: Tiered: 1%/2%/3%/4%
A8: 1.3 | B8: Legal Fees (Land Purchase) | C8: =C6*0.01 -> 180000 | D8: 0 | E8: 0 | F8: =C8-E8 -> 180000 | G8: =IFERROR(C8/INPUT!$B$19,0) -> 0.20181838 | H8: =IFERROR(E8/INPUT!$B$19,0) -> 0 | I8: ~1% of land price; verify with solicitor
A9: 1.4 | B9: Land Conversion Premium | C9: 1200000 | D9: 0 | E9: 0 | F9: =C9-E9 -> 1200000 | G9: =IFERROR(C9/INPUT!$B$19,0) -> 1.3454559 | H9: =IFERROR(E9/INPUT!$B$19,0) -> 0 | I9: Agri → Building; state authority assessment
A10: 1.5 | B10: State Authority Consent Fee | C10: 15000 | D10: 0 | E10: 0 | F10: =C10-E10 -> 15000 | G10: =IFERROR(C10/INPUT!$B$19,0) -> 0.016818199 | H10: =IFERROR(E10/INPUT!$B$19,0) -> 0 | I10: If restriction-in-interest applies
A11: 1.6 | B11: Land Valuation Fee | C11: =C6*0.0025 -> 45000 | D11: 0 | E11: 0 | F11: =C11-E11 -> 45000 | G11: =IFERROR(C11/INPUT!$B$19,0) -> 0.050454596 | H11: =IFERROR(E11/INPUT!$B$19,0) -> 0 | I11: ~0.25% of market value; bank requirement
A12: 1.7 | B12: Quit Rent & Assessment Arrears | C12: 0 | D12: 0 | E12: 0 | F12: =C12-E12 -> 0 | G12: =IFERROR(C12/INPUT!$B$19,0) -> 0 | H12: =IFERROR(E12/INPUT!$B$19,0) -> 0 | I12: Check via title search; buyer absorbs
A13: 1.8 | B13: Land Loan Interest (Holding) | C13: 900000 | D13: 0 | E13: 0 | F13: =C13-E13 -> 900000 | G13: =IFERROR(C13/INPUT!$B$19,0) -> 1.0090919 | H13: =IFERROR(E13/INPUT!$B$19,0) -> 0 | I13: Land loan interest from acquisition to launch
A14: 1.9 | B14: Contingency (Land) | C14: =SUM(C6:C13)*0.02 -> 420880 | D14: 0 | E14: 0 | F14: =C14-E14 -> 420880 | G14: =IFERROR(C14/INPUT!$B$19,0) -> 0.47189623 | H14: =IFERROR(E14/INPUT!$B$19,0) -> 0 | I14: 2% contingency on land costs
B15: PILLAR 1 TOTAL — Land Cost | C15: =SUM(C6:C14) -> 21464880 | D15: =SUM(D6:D14) -> 18000000 | E15: =SUM(E6:E14) -> 18000000 | F15: =C15-E15 -> 3464880 | G15: =IFERROR(C15/INPUT!$B$19,0) -> 24.066708 | H15: =IFERROR(E15/INPUT!$B$19,0) -> 20.181838 | I15: =IFERROR(C15/INPUT!$B$37," ") -> 0.041346715
A17: P2 | B17: PILLAR 2 · CONSTRUCTION COST | I17: Typical: 45–50% of Net GDV
A18: 2.1 | B18: Piling Works | C18: 8000000 | D18: 0 | E18: 0 | F18: =C18-E18 -> 8000000 | G18: =IFERROR(C18/INPUT!$B$19,0) -> 8.9697059 | H18: =IFERROR(E18/INPUT!$B$19,0) -> 0 | I18: Type depends on soil report (bored/driven)
A19: 2.2 | B19: Substructure / Foundation | C19: 6500000 | D19: 0 | E19: 0 | F19: =C19-E19 -> 6500000 | G19: =IFERROR(C19/INPUT!$B$19,0) -> 7.2878861 | H19: =IFERROR(E19/INPUT!$B$19,0) -> 0 | I19: Basement, raft, pile caps
A20: 2.3 | B20: Superstructure — C&S | C20: 38000000 | D20: 0 | E20: 0 | F20: =C20-E20 -> 38000000 | G20: =IFERROR(C20/INPUT!$B$19,0) -> 42.606103 | H20: =IFERROR(E20/INPUT!$B$19,0) -> 0 | I20: RC frame, slabs, beams; largest single item
A21: 2.4 | B21: Architectural Works | C21: 22000000 | D21: 0 | E21: 0 | F21: =C21-E21 -> 22000000 | G21: =IFERROR(C21/INPUT!$B$19,0) -> 24.666691 | H21: =IFERROR(E21/INPUT!$B$19,0) -> 0 | I21: Façade, partitions, doors/windows, finishes
A22: 2.5 | B22: M&E — Mechanical | C22: 9000000 | D22: 0 | E22: 0 | F22: =C22-E22 -> 9000000 | G22: =IFERROR(C22/INPUT!$B$19,0) -> 10.090919 | H22: =IFERROR(E22/INPUT!$B$19,0) -> 0 | I22: HVAC, fire suppression, lifts/escalators
A23: 2.6 | B23: M&E — Electrical | C23: 7500000 | D23: 0 | E23: 0 | F23: =C23-E23 -> 7500000 | G23: =IFERROR(C23/INPUT!$B$19,0) -> 8.4090993 | H23: =IFERROR(E23/INPUT!$B$19,0) -> 0 | I23: LV/HV distribution, lighting, ELV systems
A24: 2.7 | B24: Plumbing & Sanitary | C24: 4000000 | D24: 0 | E24: 0 | F24: =C24-E24 -> 4000000 | G24: =IFERROR(C24/INPUT!$B$19,0) -> 4.484853 | H24: =IFERROR(E24/INPUT!$B$19,0) -> 0 | I24: Internal water supply & sewerage
A25: 2.8 | B25: Landscaping (Internal) | C25: 2000000 | D25: 0 | E25: 0 | F25: =C25-E25 -> 2000000 | G25: =IFERROR(C25/INPUT!$B$19,0) -> 2.2424265 | H25: =IFERROR(E25/INPUT!$B$19,0) -> 0 | I25: Podium landscape, pool deck, gym fit-out
A26: 2.9 | B26: Preliminaries | C26: =SUM(C18:C25)*0.08 -> 7760000 | D26: 0 | E26: 0 | F26: =C26-E26 -> 7760000 | G26: =IFERROR(C26/INPUT!$B$19,0) -> 8.7006148 | H26: =IFERROR(E26/INPUT!$B$19,0) -> 0 | I26: ~8% of trade works; site mgmt, temp works, insurance
A27: 2.10 | B27: Contingency (Construction) | C27: =SUM(C18:C26)*0.05 -> 5238000 | D27: 0 | E27: 0 | F27: =C27-E27 -> 5238000 | G27: =IFERROR(C27/INPUT!$B$19,0) -> 5.872915 | H27: =IFERROR(E27/INPUT!$B$19,0) -> 0 | I27: 5% contingency; used for approved VOs
B28: PILLAR 2 TOTAL — Construction Cost | C28: =SUM(C18:C27) -> 109998000 | D28: =SUM(D18:D27) -> 0 | E28: =SUM(E18:E27) -> 0 | F28: =C28-E28 -> 109998000 | G28: =IFERROR(C28/INPUT!$B$19,0) -> 123.33121 | H28: =IFERROR(E28/INPUT!$B$19,0) -> 0 | I28: =IFERROR(C28/INPUT!$B$37," ") -> 0.2118836
A30: P3 | B30: PILLAR 3 · INFRASTRUCTURE + STATUTORY CONTRIBUTIONS | I30: Typical: 8–15% of Net GDV
A31: 3.1 | B31: Internal Roads & Driveways | C31: 3500000 | D31: 0 | E31: 0 | F31: =C31-E31 -> 3500000 | G31: =IFERROR(C31/INPUT!$B$19,0) -> 3.9242463 | H31: =IFERROR(E31/INPUT!$B$19,0) -> 0 | I31: Tarmac, curbs, road markings within site
A32: 3.2 | B32: External Road Upgrade (JKR) | C32: 1800000 | D32: 0 | E32: 0 | F32: =C32-E32 -> 1800000 | G32: =IFERROR(C32/INPUT!$B$19,0) -> 2.0181838 | H32: =IFERROR(E32/INPUT!$B$19,0) -> 0 | I32: Off-site road widening per JKR requirement
A33: 3.3 | B33: Drainage & Stormwater (JPS) | C33: 2200000 | D33: 0 | E33: 0 | F33: =C33-E33 -> 2200000 | G33: =IFERROR(C33/INPUT!$B$19,0) -> 2.4666691 | H33: =IFERROR(E33/INPUT!$B$19,0) -> 0 | I33: Internal drains + tie-in to JPS system
A34: 3.4 | B34: TNB Substation & Cabling | C34: 1500000 | D34: 0 | E34: 0 | F34: =C34-E34 -> 1500000 | G34: =IFERROR(C34/INPUT!$B$19,0) -> 1.6818199 | H34: =IFERROR(E34/INPUT!$B$19,0) -> 0 | I34: Main substation contribution + cabling to boundary
A35: 3.5 | B35: Water Supply (SYABAS/Air Sel) | C35: 900000 | D35: 0 | E35: 0 | F35: =C35-E35 -> 900000 | G35: =IFERROR(C35/INPUT!$B$19,0) -> 1.0090919 | H35: =IFERROR(E35/INPUT!$B$19,0) -> 0 | I35: Pipe laying + reservoir contribution
A36: 3.6 | B36: Sewerage (IWK / SPAN) | C36: 700000 | D36: 0 | E36: 0 | F36: =C36-E36 -> 700000 | G36: =IFERROR(C36/INPUT!$B$19,0) -> 0.78484927 | H36: =IFERROR(E36/INPUT!$B$19,0) -> 0 | I36: Connection to IWK mains or on-site STP
A37: 3.7 | B37: Telco Ducting (MCMC) | C37: 250000 | D37: 0 | E37: 0 | F37: =C37-E37 -> 250000 | G37: =IFERROR(C37/INPUT!$B$19,0) -> 0.28030331 | H37: =IFERROR(E37/INPUT!$B$19,0) -> 0 | I37: Underground telco duct network
A38: 3.8 | B38: Open Space Landscaping | C38: 1200000 | D38: 0 | E38: 0 | F38: =C38-E38 -> 1200000 | G38: =IFERROR(C38/INPUT!$B$19,0) -> 1.3454559 | H38: =IFERROR(E38/INPUT!$B$19,0) -> 0 | I38: Public open space per DA condition (10% of site)
A39: 3.9 | B39: Community Facilities | C39: 600000 | D39: 0 | E39: 0 | F39: =C39-E39 -> 600000 | G39: =IFERROR(C39/INPUT!$B$19,0) -> 0.67272795 | H39: =IFERROR(E39/INPUT!$B$19,0) -> 0 | I39: Bus stop, surau, guard house, notice board
A40: 3.10 | B40: Development Contribution (PBT) | C40: 2500000 | D40: 0 | E40: 0 | F40: =C40-E40 -> 2500000 | G40: =IFERROR(C40/INPUT!$B$19,0) -> 2.8030331 | H40: =IFERROR(E40/INPUT!$B$19,0) -> 0 | I40: Cash contribution to local authority per DA
A41: 3.11 | B41: Low-Cost Housing (in-situ build) | C41: 3000000 | D41: 0 | E41: 0 | F41: =C41-E41 -> 3000000 | G41: =IFERROR(C41/INPUT!$B$19,0) -> 3.3636397 | H41: =IFERROR(E41/INPUT!$B$19,0) -> 0 | I41: If required by state; cost minus controlled price revenue
A42: 3.12 | B42: Contingency (Infrastructure) | C42: =SUM(C31:C41)*0.05 -> 907500 | D42: 0 | E42: 0 | F42: =C42-E42 -> 907500 | G42: =IFERROR(C42/INPUT!$B$19,0) -> 1.017501 | H42: =IFERROR(E42/INPUT!$B$19,0) -> 0 | I42: 5% for scope creep in infra works
B43: PILLAR 3 TOTAL — Infrastructure + Statutory | C43: =SUM(C31:C42) -> 19057500 | D43: =SUM(D31:D42) -> 0 | E43: =SUM(E31:E42) -> 0 | F43: =C43-E43 -> 19057500 | G43: =IFERROR(C43/INPUT!$B$19,0) -> 21.367521 | H43: =IFERROR(E43/INPUT!$B$19,0) -> 0 | I43: =IFERROR(C43/INPUT!$B$37," ") -> 0.036709501
...

Sheet SUMMARY
A1: PROJECT P&L SUMMARY — Feasibility vs Actual
A2: Item | B2: Budget (RM) | C2: Committed (RM) | D2: Actual (RM) | E2: Var (RM) | F2: Budget %GDV | G2: Budget psf NFA
A3: NET GDV | B3: =INPUT!B37 -> 5.1914354e+08 | C3: =INPUT!B37 -> 5.1914354e+08 | D3: =INPUT!B37 -> 5.1914354e+08 | E3: =B3-D3 -> 0 | F3: =IFERROR(B3/SUMMARY!$B$3,0) -> 1 | G3: =IFERROR(B3/INPUT!$B$19,0) -> 582.07061
A4: P1 · Land Cost | B4: =COSTING!C15 -> 21464880 | C4: =COSTING!D15 -> 18000000 | D4: =COSTING!E15 -> 18000000 | E4: =B4-D4 -> 3464880 | F4: =IFERROR(B4/SUMMARY!$B$3,0) -> 0.041346715 | G4: =IFERROR(B4/INPUT!$B$19,0) -> 24.066708
A5: P2 · Construction | B5: =COSTING!C28 -> 109998000 | C5: =COSTING!D28 -> 0 | D5: =COSTING!E28 -> 0 | E5: =B5-D5 -> 109998000 | F5: =IFERROR(B5/SUMMARY!$B$3,0) -> 0.2118836 | G5: =IFERROR(B5/INPUT!$B$19,0) -> 123.33121
A6: P3 · Infra + Stat | B6: =COSTING!C43 -> 19057500 | C6: =COSTING!D43 -> 0 | D6: =COSTING!E43 -> 0 | E6: =B6-D6 -> 19057500 | F6: =IFERROR(B6/SUMMARY!$B$3,0) -> 0.036709501 | G6: =IFERROR(B6/INPUT!$B$19,0) -> 21.367521
A7: P4 · Professional | B7: =COSTING!C56 -> 8547370 | C7: =COSTING!D56 -> 0 | D7: =COSTING!E56 -> 0 | E7: =B7-D7 -> 8547370 | F7: =IFERROR(B7/SUMMARY!$B$3,0) -> 0.016464368 | G7: =IFERROR(B7/INPUT!$B$19,0) -> 9.5834244
A8: P5 · Finance + Mkt | B8: =COSTING!C71 -> 28289559 | C8: =COSTING!D71 -> 0 | D8: =COSTING!E71 -> 0 | E8: =B8-D8 -> 28289559 | F8: =IFERROR(B8/SUMMARY!$B$3,0) -> 0.05449275 | G8: =IFERROR(B8/INPUT!$B$19,0) -> 31.718628
A9: GROSS DEV COST | B9: =COSTING!C73 -> 1.8735731e+08 | C9: =COSTING!D73 -> 18000000 | D9: =COSTING!E73 -> 18000000 | E9: =B9-D9 -> 1.6935731e+08 | F9: =IFERROR(B9/SUMMARY!$B$3,0) -> 0.36089693 | G9: =IFERROR(B9/INPUT!$B$19,0) -> 210.0675
A10: PROFIT BEFORE TAX | B10: =B3-B9 -> 3.3178623e+08 | C10: =C3-C9 -> 5.0114354e+08 | D10: =D3-D9 -> 5.0114354e+08 | E10: =B10-D10 -> -1.6935731e+08 | F10: =IFERROR(B10/SUMMARY!$B$3,0) -> 0.63910307 | G10: =IFERROR(B10/INPUT!$B$19,0) -> 372.00311

Sheet BENCHMARK
A1: INDUSTRY PSF BENCHMARK (RM psf on GFA basis) | Source: JUBM & Langdon Seah / Market Norms
A2: Item | B2: Low (RM psf) | C2: Mid (RM psf) | D2: High (RM psf) | E2: Notes
A3: CONSTRUCTION COST (psf GFA)
A4: High-rise Resi (≥20 floors) | B4: 280 | C4: 350 | D4: 430 | E4: RC frame, standard finishes
A5: High-rise Resi (luxury) | B5: 380 | C5: 480 | D5: 600 | E5: High-spec, imported finishes
A6: Mid-rise Resi (5–19 floors) | B6: 230 | C6: 290 | D6: 360 | E6: RC / steel hybrid
A7: Landed Terraced (2-sty) | B7: 150 | C7: 190 | D7: 240 | E7: Brick & beam, standard spec
A8: Retail / Shop Lot | B8: 250 | C8: 320 | D8: 400 | E8: Incl M&E; higher loadings
A9: Industrial / Warehouse | B9: 80 | C9: 120 | D9: 160 | E9: Steel portal frame
A10: Basement Car Park (per bay) | B10: 25000 | C10: 35000 | D10: 50000 | E10: RM per bay (not psf)
A12: PILLAR COST as % of Net GDV
A13: P1 · Land Cost | B13: 15% | C13: 20% | D13: 25% | E13: City fringe 20–30%+
A14: P2 · Construction Cost | B14: 42% | C14: 47% | D14: 52% | E14: Main driver of GDC
A15: P3 · Infra + Statutory | B15: 8% | C15: 11% | D15: 15% | E15: Varies widely by DA conditions
A16: P4 · Professional Fees | B16: 3% | C16: 4% | D16: 5% | E16: Partially internalised by large devs
A17: P5 · Finance + Marketing | B17: 6% | C17: 8% | D17: 10% | E17: IDC biggest variable
A18: TOTAL GDC | B18: 74% | C18: 80% | D18: 87% | E18: → Net margin 13–26%
A20: EFFICIENCY RATIO (GFA → NFA)
A21: High-rise Residential | B21: 72% | C21: 78% | D21: 82% | E21: Cruciform core design ~72%; efficient ~80%+
A22: Serviced Apartment / SOHO | B22: 68% | C22: 73% | D22: 76% | E22: More common areas reduce efficiency
A23: Commercial Office | B23: 70% | C23: 75% | D23: 80% | E23: Open floor plate more efficient
A24: Retail Mall | B24: 55% | C24: 62% | D24: 68% | E24: Atrium, voids reduce NLA
A26: PROFESSIONAL FEE SCALE
A27: Architect (PAM scale) | B27: 2.5% | C27: 3.5% | D27: 4.5% | E27: % of construction cost
A28: Structural Engineer | B28: 1.0% | C28: 1.3% | D28: 1.8% | E28: % of C&S cost
A29: M&E Engineer | B29: 1.0% | C29: 1.3% | D29: 1.8% | E29: % of M&E cost
A30: QS | B30: 0.8% | C30: 1.0% | D30: 1.2% | E30: % of construction cost
A32: FINANCE COST INDICATORS
A33: Bridging Loan Rate (floating) | B33: BLR+0.5% | C33: BLR+1.0% | D33: BLR+2.0% | E33: BLR = 6.85% (Jun 2025)
A34: Bridging Loan LTV | B34: 55% | C34: 65% | D34: 75% | E34: % of GDV (bank-dependent)
A35: Agent Commission (Net GDV) | B35: 2.0% | C35: 2.5% | D35: 3.5% | E35: Exclusive/non-exclusive
A36: Performance Bond cost | B36: 0.3% | C36: 0.5% | D36: 0.8% | E36: Bank charge on 5% bond p.a.
